Workbook

Sheet Datos
A1: DATOS — llene esta hoja primero (celdas amarillas)
A2: N — tamaño de la población | E2: ESTADÍSTICOS DE LA MUESTRA | G2: POBLACIÓN (col. E, opcional)
A3: n — tamaño de la muestra | C3: puede escribir =F3 para usar los datos de la columna B | E3: n (nº de datos) | F3: =COUNT(B10:B1009) | G3: N (nº de datos) | H3: =COUNT(E10:E1009)
A4: Ȳ — media poblacional (si se conoce) | E4: Σ yᵢ | F4: =SUM(B10:B1009) | G4: Σ yᵢ (población) | H4: =SUM(E10:E1009)
A5: S² — varianza poblacional (si se conoce) | E5: Σ yᵢ² | F5: =SUMPRODUCT(B10:B1009,B10:B1009) | G5: Σ yᵢ² (población) | H5: =SUMPRODUCT(E10:E1009,E10:E1009)
A6: P — proporción poblacional (si se conoce) | E6: ȳ (media muestral) | F6: =IF(F3=0,"",AVERAGE(B10:B1009)) | G6: Ȳ (media poblacional) | H6: =IF(H3=0,"",AVERAGE(E10:E1009))
E7: s² (var. muestral) | F7: =IF(F3<2,"",_xlfn.VAR.S(B10:B1009)) | G7: S² (var. poblacional) | H7: =IF(H3<2,"",_xlfn.VAR.S(E10:E1009))
A8: MUESTRA: pegue aquí los datos (B = yᵢ, C = zᵢ∈{0,1} para proporciones; E = población opcional)
A9: # | B9: yᵢ (muestra) | C9: zᵢ (0/1) | E9: yᵢ (población, opcional) | F9: =SUM(C10:C1009) | G9: P verdadera (si binaria) | H9: =IF(H3=0,"",SUMIF(E10:E1009,1)/H3)
A10: 1 | E10: n_z (nº datos zᵢ) | F10: =COUNT(C10:C1009)
A11: =A10+1 | E11: p̂ = a/n_z | F11: =IF(F10=0,"",F9/F10)
A12: =A11+1
A13: =A12+1
A14: =A13+1
A15: =A14+1
A16: =A15+1
A17: =A16+1
A18: =A17+1
A19: =A18+1
A20: =A19+1
A21: =A20+1
A22: =A21+1
A23: =A22+1
... A1009: =A1008+1

Sheet Bernoulli
A1: DISEÑO: BERNOULLI
A3: 1. PARÁMETROS
A4: N — tamaño de la población | B4: =IF(Datos!B2="","",Datos!B2)
A5: n — tamaño de la muestra | B5: =IF(Datos!B3="",Datos!F3,Datos!B3) | C5: si B3 está vacía usa el nº de datos
A6: 1-α — nivel de confianza | B6: 0.95
A7: z = z(α/2) | B7: =_xlfn.NORM.S.INV((1-B6)/2)
A8: S² usada (poblacional si se conoce, si no muestral) | B8: =IF(Datos!B5<>"",Datos!B5,IF(Datos!F7="","",Datos!F7))
A9: P usada (poblacional si se conoce, si no p̂) | B9: =IF(Datos!B6<>"",Datos!B6,IF(Datos!F11="","",Datos!F11))
A10: ȳ — media muestral | B10: =IF(Datos!F6="","",Datos!F6)
A11: s² — varianza muestral | B11: =IF(Datos!F7="","",Datos!F7)
A12: σ̂² = (n-1)/n · s² | B12: =IF(Datos!F8="","",Datos!F8)
A13: Σ yᵢ (muestra) | B13: =IF(Datos!F4="","",Datos!F4)
A14: Σ yᵢ² (muestra) | B14: =IF(Datos!F5="","",Datos!F5)
A15: a — nº de éxitos (Σ zᵢ) | B15: =IF(Datos!F9="","",Datos!F9)
A16: p̂ — proporción muestral | B16: =IF(Datos!F11="","",Datos!F11)
A17: p — probabilidad de inclusión | B17: =IF(OR(B4="",B5=""),"",B5/B4) | C17: puede sobrescribir el valor calculado con otro p
A20: 2. ESTIMADORES Y VARIANZAS
A21: Estimador | B21: Valor | C21: Varianza teórica | D21: Varianza estimada | E21: EE = √V̂ | F21: IC inferior | G21: IC superior
A22: Media | B22: =IF(OR(B17="",B4=""),"",B13/(B4*B17)) | C22: =IFERROR((1-B17)/(B17*B4^2)*((B4-1)*B8+B4*B10^2),"") | D22: =IFERROR((1-B17)/(B17*B4^2)*B14,"") | E22: =IF(D22="","",SQRT(D22)) | F22: =IF(OR(B22="",E22=""),"",B22-$B$7*E22) | G22: =IF(OR(B22="",E22=""),"",B22+$B$7*E22)
A23: Total | B23: =IF(B17="","",B13/B17) | C23: =IFERROR((1-B17)/B17*((B4-1)*B8+B4*B10^2),"") | D23: =IFERROR((1-B17)/B17*B14,"") | E23: =IF(D23="","",SQRT(D23)) | F23: =IF(OR(B23="",E23=""),"",B23-$B$7*E23) | G23: =IF(OR(B23="",E23=""),"",B23+$B$7*E23)
A24: Proporción | B24: =IF(OR(B17="",B4=""),"",B15/(B4*B17)) | C24: =IFERROR((1-B17)*B9/(B17*B4),"") | D24: =IFERROR((1-B17)*B15/(B17*B4^2),"") | E24: =IF(D24="","",SQRT(D24)) | F24: =IF(OR(B24="",E24=""),"",B24-$B$7*E24) | G24: =IF(OR(B24="",E24=""),"",B24+$B$7*E24)
A27: 3. TAMAÑO DE MUESTRA
A28: V₀ — varianza máxima admitida | C28: para Ŷ o ȳ
A29: d — semiancho máximo del IC | B29: 0.05
A30: n aprox. — media (con V₀) | B30: =IF(B28="","",IFERROR(ROUNDUP(B4*((B4-1)*B8+B4*B10^2)/(B28*B4^2+((B4-1)*B8+B4*B10^2)),0),""))
A31: n aprox. — media (con d y 1-α) | B31: =IFERROR(ROUNDUP(B4*((B4-1)*B8+B4*B10^2)/(((B29/B7)^2)*B4^2+((B4-1)*B8+B4*B10^2)),0),"")
A32: n aprox. — proporción (con V₀) | B32: =IF(B28="","",IFERROR(ROUNDUP(B4*B9/(B28*B4+B9),0),""))
A33: n aprox. — proporción (con d) | B33: =IFERROR(ROUNDUP(B4*B9/(((B29/B7)^2)*B4+B9),0),"")
A36: 4. TABLA n = f(d, 1-α) (puede cambiar los valores de d y 1-α)
A37: d \ 1-α | B37: 0.9 | C37: 0.95 | D37: 0.99
A38: 0.01 | B38: =IFERROR(ROUNDUP($B$4*((((B4-1)*B8+B4*B10^2))/(((($A38/_xlfn.NORM.S.INV((1-B$37)/2))^2)*$B$4^2)+((B4-1)*B8+B4*B10^2))),0),"") | C38: =IFERROR(ROUNDUP($B$4*((((B4-1)*B8+B4*B10^2))/(((($A38/_xlfn.NORM.S.INV((1-C$37)/2))^2)*$B$4^2)+((B4-1)*B8+B4*B10^2))),0),"") | D38: =IFERROR(ROUNDUP($B$4*((((B4-1)*B8+B4*B10^2))/(((($A38/_xlfn.NORM.S.INV((1-D$37)/2))^2)*$B$4^2)+((B4-1)*B8+B4*B10^2))),0),"")
A39: 0.02 | B39: =IFERROR(ROUNDUP($B$4*((((B4-1)*B8+B4*B10^2))/(((($A39/_xlfn.NORM.S.INV((1-B$37)/2))^2)*$B$4^2)+((B4-1)*B8+B4*B10^2))),0),"") | C39: =IFERROR(ROUNDUP($B$4*((((B4-1)*B8+B4*B10^2))/(((($A39/_xlfn.NORM.S.INV((1-C$37)/2))^2)*$B$4^2)+((B4-1)*B8+B4*B10^2))),0),"") | D39: =IFERROR(ROUNDUP($B$4*((((B4-1)*B8+B4*B10^2))/(((($A39/_xlfn.NORM.S.INV((1-D$37)/2))^2)*$B$4^2)+((B4-1)*B8+B4*B10^2))),0),"")
A40: 0.05 | B40: =IFERROR(ROUNDUP($B$4*((((B4-1)*B8+B4*B10^2))/(((($A40/_xlfn.NORM.S.INV((1-B$37)/2))^2)*$B$4^2)+((B4-1)*B8+B4*B10^2))),0),"") | C40: =IFERROR(ROUNDUP($B$4*((((B4-1)*B8+B4*B10^2))/(((($A40/_xlfn.NORM.S.INV((1-C$37)/2))^2)*$B$4^2)+((B4-1)*B8+B4*B10^2))),0),"") | D40: =IFERROR(ROUNDUP($B$4*((((B4-1)*B8+B4*B10^2))/(((($A40/_xlfn.NORM.S.INV((1-D$37)/2))^2)*$B$4^2)+((B4-1)*B8+B4*B10^2))),0),"")
A42: La varianza teórica usa Σ_U yᵢ² ≈ (N-1)S² + N·Ȳ² (estimación piloto).
A43: El tamaño de muestra n ≈ N·p; p sale de la condición Var ≤ V₀ (o z·EE ≤ d).

Sheet MAS con reemplazo
A1: DISEÑO: MAS CON REEMPLAZO
A3: 1. PARÁMETROS
A4: N — tamaño de la población | B4: =IF(Datos!B2="","",Datos!B2)
A5: n — tamaño de la muestra | B5: =IF(Datos!B3="",Datos!F3,Datos!B3) | C5: si B3 está vacía usa el nº de datos
A6: 1-α — nivel de confianza | B6: 0.95
A7: z = z(α/2) | B7: =_xlfn.NORM.S.INV((1-B6)/2)
A8: S² usada (poblacional si se conoce, si no muestral) | B8: =IF(Datos!B5<>"",Datos!B5,IF(Datos!F7="","",Datos!F7))
A9: P usada (poblacional si se conoce, si no p̂) | B9: =IF(Datos!B6<>"",Datos!B6,IF(Datos!F11="","",Datos!F11))
A10: ȳ — media muestral | B10: =IF(Datos!F6="","",Datos!F6)
A11: s² — varianza muestral | B11: =IF(Datos!F7="","",Datos!F7)
A12: σ̂² = (n-1)/n · s² | B12: =IF(Datos!F8="","",Datos!F8)
A13: Σ yᵢ (muestra) | B13: =IF(Datos!F4="","",Datos!F4)
A14: Σ yᵢ² (muestra) | B14: =IF(Datos!F5="","",Datos!F5)
A15: a — nº de éxitos (Σ zᵢ) | B15: =IF(Datos!F9="","",Datos!F9)
A16: p̂ — proporción muestral | B16: =IF(Datos!F11="","",Datos!F11)
A20: 2. ESTIMADORES Y VARIANZAS
A21: Estimador | B21: Valor | C21: Varianza teórica | D21: Varianza estimada | E21: EE = √V̂ | F21: IC inferior | G21: IC superior
A22: Media | B22: =B10 | C22: =IFERROR((B4-1)/B4*B8/B5,"") | D22: =IFERROR(B11/B5,"") | E22: =IF(D22="","",SQRT(D22)) | F22: =IF(OR(B22="",E22=""),"",B22-$B$7*E22) | G22: =IF(OR(B22="",E22=""),"",B22+$B$7*E22)
A23: Total | B23: =IFERROR(B4*B10,"") | C23: =IFERROR(B4*(B4-1)*B8/B5,"") | D23: =IFERROR(B4^2*B11/B5,"") | E23: =IF(D23="","",SQRT(D23)) | F23: =IF(OR(B23="",E23=""),"",B23-$B$7*E23) | G23: =IF(OR(B23="",E23=""),"",B23+$B$7*E23)
A24: Proporción | B24: =B16 | C24: =IFERROR((B4-1)/B4*B9*(1-B9)/B5,"") | D24: =IFERROR(B16*(1-B16)/(B5-1),"") | E24: =IF(D24="","",SQRT(D24)) | F24: =IF(OR(B24="",E24=""),"",B24-$B$7*E24) | G24: =IF(OR(B24="",E24=""),"",B24+$B$7*E24)
A27: 3. TAMAÑO DE MUESTRA
A28: V₀ — varianza máxima admitida | C28: para Ŷ o ȳ
A29: d — semiancho máximo del IC | B29: 0.05
A30: n — media (con V₀) | B30: =IF(B28="","",IFERROR(ROUNDUP(B12/B28,0),""))
A31: n — media (con d y 1-α) | B31: =IFERROR(ROUNDUP(B7^2*B12/B29^2,0),"")
A32: n — proporción (con V₀) | B32: =IF(B28="","",IFERROR(ROUNDUP(B9*(1-B9)/B28,0),""))
A33: n — proporción (con d) | B33: =IFERROR(ROUNDUP(B7^2*B9*(1-B9)/B29^2,0),"")
A34: n — total (con V₀) | B34: =IF(B28="","",IFERROR(ROUNDUP(B4^2*B12/B28,0),""))
A36: 4. TABLA n = f(d, 1-α) (puede cambiar los valores de d y 1-α)
A37: d \ 1-α | B37: 0.9 | C37: 0.95 | D37: 0.99
A38: 0.01 | B38: =IFERROR(ROUNDUP(_xlfn.NORM.S.INV((1-B$37)/2)^2*$B$12/$A38^2,0),"") | C38: =IFERROR(ROUNDUP(_xlfn.NORM.S.INV((1-C$37)/2)^2*$B$12/$A38^2,0),"") | D38: =IFERROR(ROUNDUP(_xlfn.NORM.S.INV((1-D$37)/2)^2*$B$12/$A38^2,0),"")
A39: 0.02 | B39: =IFERROR(ROUNDUP(_xlfn.NORM.S.INV((1-B$37)/2)^2*$B$12/$A39^2,0),"") | C39: =IFERROR(ROUNDUP(_xlfn.NORM.S.INV((1-C$37)/2)^2*$B$12/$A39^2,0),"") | D39: =IFERROR(ROUNDUP(_xlfn.NORM.S.INV((1-D$37)/2)^2*$B$12/$A39^2,0),"")
A40: 0.05 | B40: =IFERROR(ROUNDUP(_xlfn.NORM.S.INV((1-B$37)/2)^2*$B$12/$A40^2,0),"") | C40: =IFERROR(ROUNDUP(_xlfn.NORM.S.INV((1-C$37)/2)^2*$B$12/$A40^2,0),"") | D40: =IFERROR(ROUNDUP(_xlfn.NORM.S.INV((1-D$37)/2)^2*$B$12/$A40^2,0),"")
A42: Varianzas exactas: Var(ȳ) = σ²/n con σ² = (N-1)/N · S².
A43: La tabla inferior es para la MEDIA; para la proporción cambie σ̂² por P(1-P).

Sheet MAS sin reemplazo
A1: DISEÑO: MAS SIN REEMPLAZO
A3: 1. PARÁMETROS
A4: N — tamaño de la población | B4: =IF(Datos!B2="","",Datos!B2)
A5: n — tamaño de la muestra | B5: =IF(Datos!B3="",Datos!F3,Datos!B3) | C5: si B3 está vacía usa el nº de datos
A6: 1-α — nivel de confianza | B6: 0.95
A7: z = z(α/2) | B7: =_xlfn.NORM.S.INV((1-B6)/2)
A8: S² usada (poblacional si se conoce, si no muestral) | B8: =IF(Datos!B5<>"",Datos!B5,IF(Datos!F7="","",Datos!F7))
A9: P usada (poblacional si se conoce, si no p̂) | B9: =IF(Datos!B6<>"",Datos!B6,IF(Datos!F11="","",Datos!F11))
A10: ȳ — media muestral | B10: =IF(Datos!F6="","",Datos!F6)
A11: s² — varianza muestral | B11: =IF(Datos!F7="","",Datos!F7)
A12: σ̂² = (n-1)/n · s² | B12: =IF(Datos!F8="","",Datos!F8)
A13: Σ yᵢ (muestra) | B13: =IF(Datos!F4="","",Datos!F4)
A14: Σ yᵢ² (muestra) | B14: =IF(Datos!F5="","",Datos!F5)
A15: a — nº de éxitos (Σ zᵢ) | B15: =IF(Datos!F9="","",Datos!F9)
A16: p̂ — proporción muestral | B16: =IF(Datos!F11="","",Datos!F11)
A20: 2. ESTIMADORES Y VARIANZAS
A21: Estimador | B21: Valor | C21: Varianza teórica | D21: Varianza estimada | E21: EE = √V̂ | F21: IC inferior | G21: IC superior
A22: Media | B22: =B10 | C22: =IFERROR((1-B5/B4)*B8/B5,"") | D22: =IFERROR((1-B5/B4)*B11/B5,"") | E22: =IF(D22="","",SQRT(D22)) | F22: =IF(OR(B22="",E22=""),"",B22-$B$7*E22) | G22: =IF(OR(B22="",E22=""),"",B22+$B$7*E22)
A23: Total | B23: =IFERROR(B4*B10,"") | C23: =IFERROR(B4^2*(1-B5/B4)*B8/B5,"") | D23: =IFERROR(B4^2*(1-B5/B4)*B11/B5,"") | E23: =IF(D23="","",SQRT(D23)) | F23: =IF(OR(B23="",E23=""),"",B23-$B$7*E23) | G23: =IF(OR(B23="",E23=""),"",B23+$B$7*E23)
A24: Proporción | B24: =B16 | C24: =IFERROR((1-B5/B4)*B4*B9*(1-B9)/((B4-1)*B5),"") | D24: =IFERROR((1-B5/B4)*B16*(1-B16)/(B5-1),"") | E24: =IF(D24="","",SQRT(D24)) | F24: =IF(OR(B24="",E24=""),"",B24-$B$7*E24) | G24: =IF(OR(B24="",E24=""),"",B24+$B$7*E24)
A27: 3. TAMAÑO DE MUESTRA
A28: V₀ — varianza máxima admitida | C28: para Ŷ o ȳ
A29: d — semiancho máximo del IC | B29: 0.05
A30: n — media (con V₀) | B30: =IF(B28="","",IFERROR(ROUNDUP(B4*B8/(B4*B28+B8),0),""))
A31: n — media (con d y 1-α) | B31: =IFERROR(ROUNDUP(B4*B7^2*B8/(B29^2*(B4-1)+B7^2*B8),0),"")
A32: n — proporción (con V₀) | B32: =IF(B28="","",IFERROR(ROUNDUP(B4*B9*(1-B9)/((B4-1)*B28+B9*(1-B9)),0),""))
A33: n — proporción (con d) | B33: =IFERROR(ROUNDUP(B4*B7^2*B9*(1-B9)/(B29^2*(B4-1)+B7^2*B9*(1-B9)),0),"")
A34: n — total (con V₀) | B34: =IF(B28="","",IFERROR(ROUNDUP(B4^2*B8/(B28+B4*B8),0),""))
A36: 4. TABLA n = f(d, 1-α) (puede cambiar los valores de d y 1-α)
A37: d \ 1-α | B37: 0.9 | C37: 0.95 | D37: 0.99
A38: 0.01 | B38: =IFERROR(ROUNDUP($B$4*_xlfn.NORM.S.INV((1-B$37)/2)^2*$B$8/($A38^2*($B$4-1)+_xlfn.NORM.S.INV((1-B$37)/2)^2*$B$8),0),"") | C38: =IFERROR(ROUNDUP($B$4*_xlfn.NORM.S.INV((1-C$37)/2)^2*$B$8/($A38^2*($B$4-1)+_xlfn.NORM.S.INV((1-C$37)/2)^2*$B$8),0),"") | D38: =IFERROR(ROUNDUP($B$4*_xlfn.NORM.S.INV((1-D$37)/2)^2*$B$8/($A38^2*($B$4-1)+_xlfn.NORM.S.INV((1-D$37)/2)^2*$B$8),0),"")
A39: 0.02 | B39: =IFERROR(ROUNDUP($B$4*_xlfn.NORM.S.INV((1-B$37)/2)^2*$B$8/($A39^2*($B$4-1)+_xlfn.NORM.S.INV((1-B$37)/2)^2*$B$8),0),"") | C39: =IFERROR(ROUNDUP($B$4*_xlfn.NORM.S.INV((1-C$37)/2)^2*$B$8/($A39^2*($B$4-1)+_xlfn.NORM.S.INV((1-C$37)/2)^2*$B$8),0),"") | D39: =IFERROR(ROUNDUP($B$4*_xlfn.NORM.S.INV((1-D$37)/2)^2*$B$8/($A39^2*($B$4-1)+_xlfn.NORM.S.INV((1-D$37)/2)^2*$B$8),0),"")
A40: 0.05 | B40: =IFERROR(ROUNDUP($B$4*_xlfn.NORM.S.INV((1-B$37)/2)^2*$B$8/($A40^2*($B$4-1)+_xlfn.NORM.S.INV((1-B$37)/2)^2*$B$8),0),"") | C40: =IFERROR(ROUNDUP($B$4*_xlfn.NORM.S.INV((1-C$37)/2)^2*$B$8/($A40^2*($B$4-1)+_xlfn.NORM.S.INV((1-C$37)/2)^2*$B$8),0),"") | D40: =IFERROR(ROUNDUP($B$4*_xlfn.NORM.S.INV((1-D$37)/2)^2*$B$8/($A40^2*($B$4-1)+_xlfn.NORM.S.INV((1-D$37)/2)^2*$B$8),0),"")
A42: El factor (1 - n/N) es la corrección por población finita (fpc).
A43: La tabla inferior es para la MEDIA con S²; para la proporción use P(1-P) en vez de S².

Sheet Sistemático
A1: DISEÑO: SISTEMÁTICO
A3: 1. PARÁMETROS
A4: N — tamaño de la población | B4: =IF(Datos!B2="","",Datos!B2)
A5: n — tamaño de la muestra | B5: =IF(Datos!B3="",Datos!F3,Datos!B3) | C5: si B3 está vacía usa el nº de datos
A6: 1-α — nivel de confianza | B6: 0.95
A7: z = z(α/2) | B7: =_xlfn.NORM.S.INV((1-B6)/2)
A8: S² usada (poblacional si se conoce, si no muestral) | B8: =IF(Datos!B5<>"",Datos!B5,IF(Datos!F7="","",Datos!F7))
A9: P usada (poblacional si se conoce, si no p̂) | B9: =IF(Datos!B6<>"",Datos!B6,IF(Datos!F11="","",Datos!F11)) | I9: dif² aux
A10: ȳ — media muestral | B10: =IF(Datos!F6="","",Datos!F6) | I10: =IF(OR(Datos!B10="",Datos!B11=""),"",(Datos!B11-Datos!B10)^2)
A11: s² — varianza muestral | B11: =IF(Datos!F7="","",Datos!F7) | I11: =IF(OR(Datos!B11="",Datos!B12=""),"",(Datos!B12-Datos!B11)^2)
A12: σ̂² = (n-1)/n · s² | B12: =IF(Datos!F8="","",Datos!F8) | I12: =IF(OR(Datos!B12="",Datos!B13=""),"",(Datos!B13-Datos!B12)^2)
A13: Σ yᵢ (muestra) | B13: =IF(Datos!F4="","",Datos!F4) | I13: =IF(OR(Datos!B13="",Datos!B14=""),"",(Datos!B14-Datos!B13)^2)
A14: Σ yᵢ² (muestra) | B14: =IF(Datos!F5="","",Datos!F5) | I14: =IF(OR(Datos!B14="",Datos!B15=""),"",(Datos!B15-Datos!B14)^2)
A15: a — nº de éxitos (Σ zᵢ) | B15: =IF(Datos!F9="","",Datos!F9) | I15: =IF(OR(Datos!B15="",Datos!B16=""),"",(Datos!B16-Datos!B15)^2)
A16: p̂ — proporción muestral | B16: =IF(Datos!F11="","",Datos!F11) | I16: =IF(OR(Datos!B16="",Datos!B17=""),"",(Datos!B17-Datos!B16)^2)
A17: k = N/n — intervalo de muestreo | B17: =IF(OR(B4="",B5=""),"",B4/B5) | C17: debe ser entero; arranque aleatorio r ∈ {1,...,k} | I17: =IF(OR(Datos!B17="",Datos!B18=""),"",(Datos!B18-Datos!B17)^2)
A18: ρ — correlación intraclase (0 si no se conoce) | C18: solo para la varianza teórica | I18: =IF(OR(Datos!B18="",Datos!B19=""),"",(Datos!B19-Datos!B18)^2)
A19: Σ(yᵢ₊₁−yᵢ)² (auxiliar, columna I) | B19: =IFERROR(SUM(I10:I1008),"") | I19: =IF(OR(Datos!B19="",Datos!B20=""),"",(Datos!B20-Datos!B19)^2)
A20: 2. ESTIMADORES Y VARIANZAS | I20: =IF(OR(Datos!B20="",Datos!B21=""),"",(Datos!B21-Datos!B20)^2)
A21: Estimador | B21: Valor | C21: Varianza teórica | D21: Varianza estimada | E21: EE = √V̂ | F21: IC inferior | G21: IC superior | I21: =IF(OR(Datos!B21="",Datos!B22=""),"",(Datos!B22-Datos!B21)^2)
A22: Media | B22: =B10 | C22: =IFERROR((B4-1)/B4*B8/B5*(1+(B5-1)*B18),"") | D22: =IFERROR((1-B5/B4)*B11/B5,"") | E22: =IF(D22="","",SQRT(D22)) | F22: =IF(OR(B22="",E22=""),"",B22-$B$7*E22) | G22: =IF(OR(B22="",E22=""),"",B22+$B$7*E22) | I22: =IF(OR(Datos!B22="",Datos!B23=""),"",(Datos!B23-Datos!B22)^2)
A23: Total | B23: =IFERROR(B4*B10,"") | C23: =IFERROR(B4*(B4-1)*B8/B5*(1+(B5-1)*B18),"") | D23: =IFERROR(B4^2*(1-B5/B4)*B11/B5,"") | E23: =IF(D23="","",SQRT(D23)) | F23: =IF(OR(B23="",E23=""),"",B23-$B$7*E23) | G23: =IF(OR(B23="",E23=""),"",B23+$B$7*E23) | I23: =IF(OR(Datos!B23="",Datos!B24=""),"",(Datos!B24-Datos!B23)^2)
A24: Proporción | B24: =B16 | C24: =IFERROR((1-B5/B4)*B4*B9*(1-B9)/((B4-1)*B5),"") | D24: =IFERROR((1-B5/B4)*B16*(1-B16)/(B5-1),"") | E24: =IF(D24="","",SQRT(D24)) | F24: =IF(OR(B24="",E24=""),"",B24-$B$7*E24) | G24: =IF(OR(B24="",E24=""),"",B24+$B$7*E24) | I24: =IF(OR(Datos!B24="",Datos!B25=""),"",(Datos!B25-Datos!B24)^2)
A25: Var. estimada por diferencias sucesivas (media) | B25: =IFERROR((1-B5/B4)/(2*B5*(B5-1))*B19,"") | I25: =IF(OR(Datos!B25="",Datos!B26=""),"",(Datos!B26-Datos!B25)^2)
I26: =IF(OR(Datos!B26="",Datos!B27=""),"",(Datos!B27-Datos!B26)^2)
A27: 3. TAMAÑO DE MUESTRA | I27: =IF(OR(Datos!B27="",Datos!B28=""),"",(Datos!B28-Datos!B27)^2)
A28: V₀ — varianza máxima admitida | C28: para Ŷ o ȳ | I28: =IF(OR(Datos!B28="",Datos!B29=""),"",(Datos!B29-Datos!B28)^2)
A29: d — semiancho máximo del IC | B29: 0.05 | I29: =IF(OR(Datos!B29="",Datos!B30=""),"",(Datos!B30-Datos!B29)^2)
A30: n aprox. — media (con V₀) | B30: =IF(B28="","",IFERROR(ROUNDUP(B4*B8/(B4*B28+B8),0),"")) | I30: =IF(OR(Datos!B30="",Datos!B31=""),"",(Datos!B31-Datos!B30)^2)
A31: n aprox. — media (con d y 1-α) | B31: =IFERROR(ROUNDUP(B4*B7^2*B8/(B29^2*(B4-1)+B7^2*B8),0),"") | I31: =IF(OR(Datos!B31="",Datos!B32=""),"",(Datos!B32-Datos!B31)^2)
A32: n aprox. — proporción (con V₀) | B32: =IF(B28="","",IFERROR(ROUNDUP(B4*B9*(1-B9)/((B4-1)*B28+B9*(1-B9)),0),"")) | I32: =IF(OR(Datos!B32="",Datos!B33=""),"",(Datos!B33-Datos!B32)^2)
A33: n aprox. — proporción (con d) | B33: =IFERROR(ROUNDUP(B4*B7^2*B9*(1-B9)/(B29^2*(B4-1)+B7^2*B9*(1-B9)),0),"") | I33: =IF(OR(Datos!B33="",Datos!B34=""),"",(Datos!B34-Datos!B33)^2)
I34: =IF(OR(Datos!B34="",Datos!B35=""),"",(Datos!B35-Datos!B34)^2)
I35: =IF(OR(Datos!B35="",Datos!B36=""),"",(Datos!B36-Datos!B35)^2)
A36: 4. TABLA n = f(d, 1-α) (puede cambiar los valores de d y 1-α) | I36: =IF(OR(Datos!B36="",Datos!B37=""),"",(Datos!B37-Datos!B36)^2)
A37: d \ 1-α | B37: 0.9 | C37: 0.95 | D37: 0.99 | I37: =IF(OR(Datos!B37="",Datos!B38=""),"",(Datos!B38-Datos!B37)^2)
A38: 0.01 | B38: =IFERROR(ROUNDUP($B$4*_xlfn.NORM.S.INV((1-B$37)/2)^2*$B$8/($A38^2*($B$4-1)+_xlfn.NORM.S.INV((1-B$37)/2)^2*$B$8),0),"") | C38: =IFERROR(ROUNDUP($B$4*_xlfn.NORM.S.INV((1-C$37)/2)^2*$B$8/($A38^2*($B$4-1)+_xlfn.NORM.S.INV((1-C$37)/2)^2*$B$8),0),"") | D38: =IFERROR(ROUNDUP($B$4*_xlfn.NORM.S.INV((1-D$37)/2)^2*$B$8/($A38^2*($B$4-1)+_xlfn.NORM.S.INV((1-D$37)/2)^2*$B$8),0),"") | I38: =IF(OR(Datos!B38="",Datos!B39=""),"",(Datos!B39-Datos!B38)^2)
A39: 0.02 | B39: =IFERROR(ROUNDUP($B$4*_xlfn.NORM.S.INV((1-B$37)/2)^2*$B$8/($A39^2*($B$4-1)+_xlfn.NORM.S.INV((1-B$37)/2)^2*$B$8),0),"") | C39: =IFERROR(ROUNDUP($B$4*_xlfn.NORM.S.INV((1-C$37)/2)^2*$B$8/($A39^2*($B$4-1)+_xlfn.NORM.S.INV((1-C$37)/2)^2*$B$8),0),"") | D39: =IFERROR(ROUNDUP($B$4*_xlfn.NORM.S.INV((1-D$37)/2)^2*$B$8/($A39^2*($B$4-1)+_xlfn.NORM.S.INV((1-D$37)/2)^2*$B$8),0),"") | I39: =IF(OR(Datos!B39="",Datos!B40=""),"",(Datos!B40-Datos!B39)^2)
A40: 0.05 | B40: =IFERROR(ROUNDUP($B$4*_xlfn.NORM.S.INV((1-B$37)/2)^2*$B$8/($A40^2*($B$4-1)+_xlfn.NORM.S.INV((1-B$37)/2)^2*$B$8),0),"") | C40: =IFERROR(ROUNDUP($B$4*_xlfn.NORM.S.INV((1-C$37)/2)^2*$B$8/($A40^2*($B$4-1)+_xlfn.NORM.S.INV((1-C$37)/2)^2*$B$8),0),"") | D40: =IFERROR(ROUNDUP($B$4*_xlfn.NORM.S.INV((1-D$37)/2)^2*$B$8/($A40^2*($B$4-1)+_xlfn.NORM.S.INV((1-D$37)/2)^2*$B$8),0),"") | I40: =IF(OR(Datos!B40="",Datos!B41=""),"",(Datos!B41-Datos!B40)^2)
I41: =IF(OR(Datos!B41="",Datos!B42=""),"",(Datos!B42-Datos!B41)^2)
...

Sheet Fórmulas LaTeX
A1: FÓRMULAS EN LaTeX — referencia rápida para otros diseños
A3: NOTACIÓN GENERAL
B4: \(N\): tamaño de la población; \(n\): tamaño de la muestra; \(y_i\): valor de la variable en la unidad \(i\); \(a=\sum z_i\): nº de éxitos; \(z_{\alpha/2}\): cuantil normal.
B5: \(\bar{Y}=\tfrac{1}{N}\sum_U y_i\); \(S^2=\tfrac{1}{N-1}\sum_U (y_i-\bar Y)^2\); \(\sigma^2=\tfrac{N-1}{N}S^2\); \(\hat P = a/n\); \(V_0\): varianza objetivo; \(d\): semiancho del IC.
A7: 1. MUESTREO BERNOULLI (inclusión con probabilidad \(p\))
B8: Estimadores: \(\hat Y_B=\tfrac{1}{p}\sum_{i\in s} y_i\); \(\hat{\bar Y}_B=\tfrac{1}{Np}\sum_{i\in s} y_i\); \(\hat P_B=\tfrac{a}{Np}\).
B9: Varianzas teóricas: \(\mathrm{Var}(\hat Y_B)=\tfrac{1-p}{p}\sum_U y_i^2\); \(\mathrm{Var}(\hat{\bar Y}_B)=\tfrac{1-p}{pN^2}\sum_U y_i^2\); \(\mathrm{Var}(\hat P_B)=\tfrac{(1-p)P}{pN}\).
B10: Varianzas estimadas (insesgadas): \(\hat v(\hat Y_B)=\tfrac{1-p}{p}\sum_s y_i^2\); \(\hat v(\hat{\bar Y}_B)=\tfrac{1-p}{pN^2}\sum_s y_i^2\); \(\hat v(\hat P_B)=\tfrac{(1-p)a}{pN^2}\).
B11: Tamaño de muestra: con \(\sum_U y_i^2 \approx (N-1)S^2+N\bar Y^2\): \(p^{\*}=\dfrac{\sum_U y_i^2}{V_0 N^2+\sum_U y_i^2}\) (use \(V_0=(d/z_{\alpha/2})^2\) para error \(d\)); \(n\approx N\,p^{\*}\). Para proporción: \(n\approx \dfrac{NP}{V_0 N+P}\).
A13: 2. MAS CON REEMPLAZO
B14: Estimadores: \(\bar y=\tfrac{1}{n}\sum_s y_i\); \(\hat Y=N\bar y\); \(\hat P=\tfrac{a}{n}\).
B15: Varianzas teóricas: \(\mathrm{Var}(\bar y)=\tfrac{N-1}{N}\tfrac{S^2}{n}=\tfrac{\sigma^2}{n}\); \(\mathrm{Var}(\hat Y)=\tfrac{N(N-1)S^2}{n}\); \(\mathrm{Var}(\hat P)=\tfrac{N-1}{N}\tfrac{P(1-P)}{n}\).
B16: Varianzas estimadas: \(\hat v(\bar y)=\tfrac{s^2}{n}\); \(\hat v(\hat Y)=\tfrac{N^2 s^2}{n}\); \(\hat v(\hat P)=\tfrac{\hat P(1-\hat P)}{n-1}\).
B17: Tamaños de muestra: media \(n=\dfrac{\sigma^2}{V_0}=\dfrac{z_{\alpha/2}^2\,\sigma^2}{d^2}\); proporción \(n=\dfrac{P(1-P)}{V_0}=\dfrac{z_{\alpha/2}^2 P(1-P)}{d^2}\); total \(n=\dfrac{N^2\sigma^2}{V_0}\).
A19: 3. MAS SIN REEMPLAZO (fpc \(=1- frac{n}{N}\))
B20: Estimadores: \(\bar y=\tfrac{1}{n}\sum_s y_i\); \(\hat Y=N\bar y\); \(\hat P=\tfrac{a}{n}\).
B21: Varianzas teóricas: \(\mathrm{Var}(\bar y)=\bigl(1-\tfrac{n}{N}\bigr)\tfrac{S^2}{n}\); \(\mathrm{Var}(\hat Y)=N^2\bigl(1-\tfrac{n}{N}\bigr)\tfrac{S^2}{n}\); \(\mathrm{Var}(\hat P)=\tfrac{N-n}{N-1}\tfrac{P(1-P)}{n}\).
B22: Varianzas estimadas: \(\hat v(\bar y)=\bigl(1-\tfrac{n}{N}\bigr)\tfrac{s^2}{n}\); \(\hat v(\hat Y)=N^2\bigl(1-\tfrac{n}{N}\bigr)\tfrac{s^2}{n}\); \(\hat v(\hat P)=\bigl(1-\tfrac{n}{N}\bigr)\tfrac{\hat P(1-\hat P)}{n-1}\).
B23: Tamaños de muestra: media \(n=\dfrac{N S^2}{N V_0+S^2}=\dfrac{N z_{\alpha/2}^2 S^2}{d^2(N-1)+z_{\alpha/2}^2 S^2}\); proporción \(n=\dfrac{N P(1-P)}{(N-1)V_0+P(1-P)}\); total \(n=\dfrac{N^2 S^2}{V_0+NS^2}\).
A25: 4. MUESTREO SISTEMÁTICO (k = N/n, arranque aleatorio r ∈ {1,…,k})
B26: Estimadores: \(\bar y_{sys}=\tfrac{1}{n}\sum_s y_i\); \(\hat Y_{sys}=N\bar y_{sys}\). No hay estimador insesgado de la varianza.
B27: Varianza teórica (correlación intraclase \(\rho\)): \(\mathrm{Var}(\bar y_{sys})=\tfrac{N-1}{N}\tfrac{S^2}{n}\bigl[1+(n-1)\rho\bigr]\); exacta sobre las \(k\) muestras posibles: \(\tfrac{1}{k}\sum_{r=1}^{k}(\bar y_r-\bar Y)^2\).
B28: Varianzas estimadas: aprox. MAS \(\hat v=\bigl(1-\tfrac{n}{N}\bigr)\tfrac{s^2}{n}\); diferencias sucesivas (Wolter): \(\hat v=\dfrac{1-n/N}{2n(n-1)}\sum_{i=1}^{n-1}(y_{i+1}-y_i)^2\).
B29: Tamaño de muestra: aproximación MAS sin reemplazo (misma fórmula), \(n=\dfrac{N S^2}{N V_0+S^2}\).
A31: INTERVALOS DE CONFIANZA (todos los diseños)
B32: \(IC_{1-\alpha}(\theta):\ \hat\theta \pm z_{\alpha/2}\sqrt{\hat v(\hat\theta)}\); \(d=z_{\alpha/2}\sqrt{V_0}\Rightarrow V_0=(d/z_{\alpha/2})^2\). \(z_{0.05}=1.645,\ z_{0.025}=1.96,\ z_{0.005}=2.576\).
